2020-05-09 18:34:17,575 INFO: Microblog startup [in C:\misc\CS\Projects\microblog\app\__init__.py:67]
2020-05-09 18:34:17,586 INFO: Microblog startup [in C:\misc\CS\Projects\microblog\app\__init__.py:85]
2020-05-09 18:34:17,586 INFO: Microblog startup [in C:\misc\CS\Projects\microblog\app\__init__.py:85]
2020-05-09 18:40:29,864 INFO: Microblog startup [in C:\misc\CS\Projects\microblog\app\__init__.py:67]
2020-05-09 18:40:29,872 INFO: Microblog startup [in C:\misc\CS\Projects\microblog\app\__init__.py:85]
2020-05-09 18:40:29,872 INFO: Microblog startup [in C:\misc\CS\Projects\microblog\app\__init__.py:85]
2020-05-09 18:40:49,679 ERROR: Exception on /auth/reset_password_request [POST] [in c:\misc\cs\projects\microblog\venv\lib\site-packages\flask\app.py:1891]
Traceback (most recent call last):
  File "c:\misc\cs\projects\microblog\venv\lib\site-packages\flask\app.py", line 2446, in wsgi_app
    response = self.full_dispatch_request()
  File "c:\misc\cs\projects\microblog\venv\lib\site-packages\flask\app.py", line 1951, in full_dispatch_request
    rv = self.handle_user_exception(e)
  File "c:\misc\cs\projects\microblog\venv\lib\site-packages\flask\app.py", line 1820, in handle_user_exception
    reraise(exc_type, exc_value, tb)
  File "c:\misc\cs\projects\microblog\venv\lib\site-packages\flask\_compat.py", line 39, in reraise
    raise value
  File "c:\misc\cs\projects\microblog\venv\lib\site-packages\flask\app.py", line 1949, in full_dispatch_request
    rv = self.dispatch_request()
  File "c:\misc\cs\projects\microblog\venv\lib\site-packages\flask\app.py", line 1935, in dispatch_request
    return self.view_functions[rule.endpoint](**req.view_args)
  File "C:\misc\CS\Projects\microblog\app\auth\routes.py", line 54, in reset_password_request
    send_password_reset_email(user)
  File "C:\misc\CS\Projects\microblog\app\auth\email.py", line 15, in send_password_reset_email
    sender=app.config['ADMINS'][0],
NameError: name 'app' is not defined
2020-05-09 18:40:49,679 ERROR: Exception on /auth/reset_password_request [POST] [in c:\misc\cs\projects\microblog\venv\lib\site-packages\flask\app.py:1891]
Traceback (most recent call last):
  File "c:\misc\cs\projects\microblog\venv\lib\site-packages\flask\app.py", line 2446, in wsgi_app
    response = self.full_dispatch_request()
  File "c:\misc\cs\projects\microblog\venv\lib\site-packages\flask\app.py", line 1951, in full_dispatch_request
    rv = self.handle_user_exception(e)
  File "c:\misc\cs\projects\microblog\venv\lib\site-packages\flask\app.py", line 1820, in handle_user_exception
    reraise(exc_type, exc_value, tb)
  File "c:\misc\cs\projects\microblog\venv\lib\site-packages\flask\_compat.py", line 39, in reraise
    raise value
  File "c:\misc\cs\projects\microblog\venv\lib\site-packages\flask\app.py", line 1949, in full_dispatch_request
    rv = self.dispatch_request()
  File "c:\misc\cs\projects\microblog\venv\lib\site-packages\flask\app.py", line 1935, in dispatch_request
    return self.view_functions[rule.endpoint](**req.view_args)
  File "C:\misc\CS\Projects\microblog\app\auth\routes.py", line 54, in reset_password_request
    send_password_reset_email(user)
  File "C:\misc\CS\Projects\microblog\app\auth\email.py", line 15, in send_password_reset_email
    sender=app.config['ADMINS'][0],
NameError: name 'app' is not defined
2020-05-09 18:43:18,733 INFO: Microblog startup [in C:\misc\CS\Projects\microblog\app\__init__.py:67]
2020-05-09 18:43:18,734 INFO: Microblog startup [in C:\misc\CS\Projects\microblog\app\__init__.py:85]
2020-05-09 18:43:18,734 INFO: Microblog startup [in C:\misc\CS\Projects\microblog\app\__init__.py:85]
2020-05-09 22:34:39,076 INFO: Microblog startup [in C:\misc\CS\Projects\microblog\app\__init__.py:67]
2020-05-09 22:34:39,084 INFO: Microblog startup [in C:\misc\CS\Projects\microblog\app\__init__.py:85]
2020-05-09 22:34:39,084 INFO: Microblog startup [in C:\misc\CS\Projects\microblog\app\__init__.py:85]
2020-05-09 22:54:28,585 INFO: Microblog startup [in C:\misc\CS\Projects\microblog\app\__init__.py:66]
2020-05-09 22:54:28,594 INFO: Microblog startup [in C:\misc\CS\Projects\microblog\app\__init__.py:84]
2020-05-09 22:54:28,594 INFO: Microblog startup [in C:\misc\CS\Projects\microblog\app\__init__.py:84]
2020-05-09 22:54:36,100 ERROR: Exception on / [GET] [in c:\misc\cs\projects\microblog\venv\lib\site-packages\flask\app.py:1891]
Traceback (most recent call last):
  File "c:\misc\cs\projects\microblog\venv\lib\site-packages\flask\app.py", line 2446, in wsgi_app
    response = self.full_dispatch_request()
  File "c:\misc\cs\projects\microblog\venv\lib\site-packages\flask\app.py", line 1951, in full_dispatch_request
    rv = self.handle_user_exception(e)
  File "c:\misc\cs\projects\microblog\venv\lib\site-packages\flask\app.py", line 1820, in handle_user_exception
    reraise(exc_type, exc_value, tb)
  File "c:\misc\cs\projects\microblog\venv\lib\site-packages\flask\_compat.py", line 39, in reraise
    raise value
  File "c:\misc\cs\projects\microblog\venv\lib\site-packages\flask\app.py", line 1947, in full_dispatch_request
    rv = self.preprocess_request()
  File "c:\misc\cs\projects\microblog\venv\lib\site-packages\flask\app.py", line 2241, in preprocess_request
    rv = func()
  File "C:\misc\CS\Projects\microblog\app\main\routes.py", line 17, in before_request
    g.locale = str(get_locale())
  File "c:\misc\cs\projects\microblog\venv\lib\site-packages\flask_babel\__init__.py", line 247, in get_locale
    babel = current_app.extensions['babel']
KeyError: 'babel'
2020-05-09 22:54:36,100 ERROR: Exception on / [GET] [in c:\misc\cs\projects\microblog\venv\lib\site-packages\flask\app.py:1891]
Traceback (most recent call last):
  File "c:\misc\cs\projects\microblog\venv\lib\site-packages\flask\app.py", line 2446, in wsgi_app
    response = self.full_dispatch_request()
  File "c:\misc\cs\projects\microblog\venv\lib\site-packages\flask\app.py", line 1951, in full_dispatch_request
    rv = self.handle_user_exception(e)
  File "c:\misc\cs\projects\microblog\venv\lib\site-packages\flask\app.py", line 1820, in handle_user_exception
    reraise(exc_type, exc_value, tb)
  File "c:\misc\cs\projects\microblog\venv\lib\site-packages\flask\_compat.py", line 39, in reraise
    raise value
  File "c:\misc\cs\projects\microblog\venv\lib\site-packages\flask\app.py", line 1947, in full_dispatch_request
    rv = self.preprocess_request()
  File "c:\misc\cs\projects\microblog\venv\lib\site-packages\flask\app.py", line 2241, in preprocess_request
    rv = func()
  File "C:\misc\CS\Projects\microblog\app\main\routes.py", line 17, in before_request
    g.locale = str(get_locale())
  File "c:\misc\cs\projects\microblog\venv\lib\site-packages\flask_babel\__init__.py", line 247, in get_locale
    babel = current_app.extensions['babel']
KeyError: 'babel'
2020-05-09 22:55:35,046 INFO: Microblog startup [in C:\misc\CS\Projects\microblog\app\__init__.py:67]
2020-05-09 22:55:35,054 INFO: Microblog startup [in C:\misc\CS\Projects\microblog\app\__init__.py:85]
2020-05-09 22:55:35,054 INFO: Microblog startup [in C:\misc\CS\Projects\microblog\app\__init__.py:85]
2020-05-09 22:55:36,751 ERROR: Exception on / [GET] [in c:\misc\cs\projects\microblog\venv\lib\site-packages\flask\app.py:1891]
Traceback (most recent call last):
  File "c:\misc\cs\projects\microblog\venv\lib\site-packages\flask\app.py", line 2446, in wsgi_app
    response = self.full_dispatch_request()
  File "c:\misc\cs\projects\microblog\venv\lib\site-packages\flask\app.py", line 1951, in full_dispatch_request
    rv = self.handle_user_exception(e)
  File "c:\misc\cs\projects\microblog\venv\lib\site-packages\flask\app.py", line 1820, in handle_user_exception
    reraise(exc_type, exc_value, tb)
  File "c:\misc\cs\projects\microblog\venv\lib\site-packages\flask\_compat.py", line 39, in reraise
    raise value
  File "c:\misc\cs\projects\microblog\venv\lib\site-packages\flask\app.py", line 1949, in full_dispatch_request
    rv = self.dispatch_request()
  File "c:\misc\cs\projects\microblog\venv\lib\site-packages\flask\app.py", line 1935, in dispatch_request
    return self.view_functions[rule.endpoint](**req.view_args)
  File "c:\misc\cs\projects\microblog\venv\lib\site-packages\flask_login\utils.py", line 271, in decorated_view
    return current_app.login_manager.unauthorized()
  File "c:\misc\cs\projects\microblog\venv\lib\site-packages\flask_login\login_manager.py", line 165, in unauthorized
    flash(self.login_message, category=self.login_message_category)
  File "c:\misc\cs\projects\microblog\venv\lib\site-packages\flask\helpers.py", line 423, in flash
    session["_flashes"] = flashes
  File "c:\misc\cs\projects\microblog\venv\lib\site-packages\werkzeug\local.py", line 350, in __setitem__
    self._get_current_object()[key] = value
  File "c:\misc\cs\projects\microblog\venv\lib\site-packages\flask\sessions.py", line 103, in _fail
    "The session is unavailable because no secret "
RuntimeError: The session is unavailable because no secret key was set.  Set the secret_key on the application to something unique and secret.
